Workbook

Sheet AB Test Analysis
A1: Milestone | A/B Testing for H&M | F1: group | G1: subject line | H1: opened
F2: control | G2: =IF(ABTest[[#This Row],[group]]="control","20% off + free shipping","Your last chance to score 20% off + free shipping") -> 20% off + free shipping | H2: 0
A3: • All of your answers should be typed or pasted into the grey boxes. • Questions with grey answer boxes expect a specific answer. Once you input the correct answer, the question number box will change from blue to green. • Questions with yellow answer boxes are free-response questions. There will be no change in the question number boxes (in blue), regardless of your answer. • Hover your cursor over the blue hint box to get a helpful hint! | F3: control | G3: =IF(ABTest[[#This Row],[group]]="control","20% off + free shipping","Your last chance to score 20% off + free shipping") -> 20% off + free shipping | H3: 0
F4: control | G4: =IF(ABTest[[#This Row],[group]]="control","20% off + free shipping","Your last chance to score 20% off + free shipping") -> 20% off + free shipping | H4: 0
F5: test | G5: =IF(ABTest[[#This Row],[group]]="control","20% off + free shipping","Your last chance to score 20% off + free shipping") -> Your last chance to score 20% off + free shipping | H5: 0
F6: test | G6: =IF(ABTest[[#This Row],[group]]="control","20% off + free shipping","Your last chance to score 20% off + free shipping") -> Your last chance to score 20% off + free shipping | H6: 0
F7: test | G7: =IF(ABTest[[#This Row],[group]]="control","20% off + free shipping","Your last chance to score 20% off + free shipping") -> Your last chance to score 20% off + free shipping | H7: 0
F8: control | G8: =IF(ABTest[[#This Row],[group]]="control","20% off + free shipping","Your last chance to score 20% off + free shipping") -> 20% off + free shipping | H8: 0
F9: control | G9: =IF(ABTest[[#This Row],[group]]="control","20% off + free shipping","Your last chance to score 20% off + free shipping") -> 20% off + free shipping | H9: 0
F10: test | G10: =IF(ABTest[[#This Row],[group]]="control","20% off + free shipping","Your last chance to score 20% off + free shipping") -> Your last chance to score 20% off + free shipping | H10: 1
F11: test | G11: =IF(ABTest[[#This Row],[group]]="control","20% off + free shipping","Your last chance to score 20% off + free shipping") -> Your last chance to score 20% off + free shipping | H11: 0
F12: test | G12: =IF(ABTest[[#This Row],[group]]="control","20% off + free shipping","Your last chance to score 20% off + free shipping") -> Your last chance to score 20% off + free shipping | H12: 0
F13: test | G13: =IF(ABTest[[#This Row],[group]]="control","20% off + free shipping","Your last chance to score 20% off + free shipping") -> Your last chance to score 20% off + free shipping | H13: 0
A14: Part 1: A/B Test Design & Identifying Potential Issues | F14: control | G14: =IF(ABTest[[#This Row],[group]]="control","20% off + free shipping","Your last chance to score 20% off + free shipping") -> 20% off + free shipping | H14: 0
F15: control | G15: =IF(ABTest[[#This Row],[group]]="control","20% off + free shipping","Your last chance to score 20% off + free shipping") -> 20% off + free shipping | H15: 1
A16: 1 | B16: In a sentence or two, state the null hypothesis for H&M's A/B test. | F16: test | G16: =IF(ABTest[[#This Row],[group]]="control","20% off + free shipping","Your last chance to score 20% off + free shipping") -> Your last chance to score 20% off + free shipping | H16: 0
A17: Changing the H&M's subject line from "The appearance of 20% off + free shipping" to "Your last chance to score 20% off + free shipping" will result in no change/Decrease in open rates for the email. | F17: control | G17: =IF(ABTest[[#This Row],[group]]="control","20% off + free shipping","Your last chance to score 20% off + free shipping") -> 20% off + free shipping | H17: 0
F18: control | G18: =IF(ABTest[[#This Row],[group]]="control","20% off + free shipping","Your last chance to score 20% off + free shipping") -> 20% off + free shipping | H18: 0
A19: 2 | B19: In a sentence or two, state the alternative hypothesis for H&M's A/B test. | F19: test | G19: =IF(ABTest[[#This Row],[group]]="control","20% off + free shipping","Your last chance to score 20% off + free shipping") -> Your last chance to score 20% off + free shipping | H19: 0
A20: Changing the H&M's subject line from "The appearance of 20% off + free shipping" to "Your last chance to score 20% off + free shipping" will result in an increase in open rates for the email. | F20: test | G20: =IF(ABTest[[#This Row],[group]]="control","20% off + free shipping","Your last chance to score 20% off + free shipping") -> Your last chance to score 20% off + free shipping | H20: 0
F21: control | G21: =IF(ABTest[[#This Row],[group]]="control","20% off + free shipping","Your last chance to score 20% off + free shipping") -> 20% off + free shipping | H21: 0
A22: Use the A/B Test Sample Size Calculator linked below to help you answer the following questions. | F22: test | G22: =IF(ABTest[[#This Row],[group]]="control","20% off + free shipping","Your last chance to score 20% off + free shipping") -> Your last chance to score 20% off + free shipping | H22: 0
A23: =HYPERLINK("https://www.statsig.com/calculator","A/B Test Sample Size Calculator") -> A/B Test Sample Size Calculator | F23: control | G23: =IF(ABTest[[#This Row],[group]]="control","20% off + free shipping","Your last chance to score 20% off + free shipping") -> 20% off + free shipping | H23: 0
A24: Historically, promotional emails have had an open rate of 18%. The company wants to see the new subject line increase that to an open rate of 20%. | F24: control | G24: =IF(ABTest[[#This Row],[group]]="control","20% off + free shipping","Your last chance to score 20% off + free shipping") -> 20% off + free shipping | H24: 0
F25: test | G25: =IF(ABTest[[#This Row],[group]]="control","20% off + free shipping","Your last chance to score 20% off + free shipping") -> Your last chance to score 20% off + free shipping | H25: 1
A26: 3 | B26: What is the minimum detectable effect associated with that increase in open rate? | C26: 0.11 | D26: Hint! | F26: control | G26: =IF(ABTest[[#This Row],[group]]="control","20% off + free shipping","Your last chance to score 20% off + free shipping") -> 20% off + free shipping | H26: 0
F27: control | G27: =IF(ABTest[[#This Row],[group]]="control","20% off + free shipping","Your last chance to score 20% off + free shipping") -> 20% off + free shipping | H27: 0
A28: 4 | B28: What total sample size is required to reliably detect that level of increase? | C28: 9300 | D28: Hint! | F28: test | G28: =IF(ABTest[[#This Row],[group]]="control","20% off + free shipping","Your last chance to score 20% off + free shipping") -> Your last chance to score 20% off + free shipping | H28: 0
F29: test | G29: =IF(ABTest[[#This Row],[group]]="control","20% off + free shipping","Your last chance to score 20% off + free shipping") -> Your last chance to score 20% off + free shipping | H29: 1
A30: Before launching any A/B test, it’s crucial to identify potential risks or confounding factors that could skew the results. As the analyst, you need to be prepared to be asked "How do we know if this test is valid?" | F30: test | G30: =IF(ABTest[[#This Row],[group]]="control","20% off + free shipping","Your last chance to score 20% off + free shipping") -> Your last chance to score 20% off + free shipping | H30: 0
F31: control | G31: =IF(ABTest[[#This Row],[group]]="control","20% off + free shipping","Your last chance to score 20% off + free shipping") -> 20% off + free shipping | H31: 0 | J31: =SUM(H2:H9437) -> 1730
A32: 5 | B32: Use ChatGPT to generate a list of confounding factors by asking "What factors could skew the results of an A/B test like this, and how might they influence our findings or effect the results?" You might also try "What are common mistakes to avoid when designing an A/B test?" After reviewing ChatGPT’s response, identify at least two confounding factors that could impact the experiment. Write a develop a brief strategy (one-to-two sentences) for how you would mitigate these issues if you were a part of designing a similar A/B test. | F32: control | G32: =IF(ABTest[[#This Row],[group]]="control","20% off + free shipping","Your last chance to score 20% off + free shipping") -> 20% off + free shipping | H32: 0
F33: control | G33: =IF(ABTest[[#This Row],[group]]="control","20% off + free shipping","Your last chance to score 20% off + free shipping") -> 20% off + free shipping | H33: 0
F34: control | G34: =IF(ABTest[[#This Row],[group]]="control","20% off + free shipping","Your last chance to score 20% off + free shipping") -> 20% off + free shipping | H34: 0
F35: test | G35: =IF(ABTest[[#This Row],[group]]="control","20% off + free shipping","Your last chance to score 20% off + free shipping") -> Your last chance to score 20% off + free shipping | H35: 0
F36: test | G36: =IF(ABTest[[#This Row],[group]]="control","20% off + free shipping","Your last chance to score 20% off + free shipping") -> Your last chance to score 20% off + free shipping | H36: 0
F37: test | G37: =IF(ABTest[[#This Row],[group]]="control","20% off + free shipping","Your last chance to score 20% off + free shipping") -> Your last chance to score 20% off + free shipping | H37: 0
F38: test | G38: =IF(ABTest[[#This Row],[group]]="control","20% off + free shipping","Your last chance to score 20% off + free shipping") -> Your last chance to score 20% off + free shipping | H38: 0
A39: One cofounding factor that could impact the experiment could be delivery time; which impacts when people are available to check their email and see the message. Additionally, is the device they are opening the email on, Whether that be phone or desktop the subject line could be truncated on mobile phones. To mitigate these issues you can make sure the emails are going out at the same time and design the subject line so that the offer is at the front. | F39: control | G39: =IF(ABTest[[#This Row],[group]]="control","20% off + free shipping","Your last chance to score 20% off + free shipping") -> 20% off + free shipping | H39: 0
F40: test | G40: =IF(ABTest[[#This Row],[group]]="control","20% off + free shipping","Your last chance to score 20% off + free shipping") -> Your last chance to score 20% off + free shipping | H40: 1
...

Sheet PivotTable
A9: Your actual PivotTable should go below this line.
B11: Count of subject line | C11: Column Labels
B12: Row Labels | C12: 0 | D12: 1 | E12: Grand Total
B13: control | C13: 3928 | D13: 836 | E13: 4764
B14: test | C14: 3779 | D14: 894 | E14: 4673
B15: Grand Total | C15: 7707 | D15: 1730 | E15: 9437

Sheet Solutions
A1: Question | B1: Low Bound | C1: High Bound | D1: free-response-solution
A2: 1 | B2: free response | D2: =IF(ISBLANK(INDEX('AB Test Analysis'!$A$17:$C$18,1,1)), "no solution", IF(ISERROR(INDEX('AB Test Analysis'!$A$17:$C$18,1,1)), "error in parsing the solution", INDEX('AB Test Analysis'!$A$17:$C$18,1,1))) -> Changing the H&M's subject line from "The appearance of 20% off + free shipping" to "Your last chance to score 20% off + free shipping" will result in no change/Decrease in open rates for the email.
A3: 2 | B3: free response | D3: =IF(ISBLANK(INDEX('AB Test Analysis'!$A$20:$C$21,1,1)), "no solution", IF(ISERROR(INDEX('AB Test Analysis'!$A$20:$C$21,1,1)), "error in parsing the solution", INDEX('AB Test Analysis'!$A$20:$C$21,1,1))) -> Changing the H&M's subject line from "The appearance of 20% off + free shipping" to "Your last chance to score 20% off + free shipping" will result in an increase in open rates for the email.
A4: 3 | B4: 0.11 | C4: 0.1112 | D4: =IF(ISBLANK(INDEX('AB Test Analysis'!$C$26:$C$27,1,1)), "no solution", IF(ISERROR(INDEX('AB Test Analysis'!$C$26:$C$27,1,1)), "error in parsing the solution", INDEX('AB Test Analysis'!$C$26:$C$27,1,1))) -> 0.11
A5: 4 | B5: 9300 | C5: 9400 | D5: =IF(ISBLANK(INDEX('AB Test Analysis'!$C$28:$C$29,1,1)), "no solution", IF(ISERROR(INDEX('AB Test Analysis'!$C$28:$C$29,1,1)), "error in parsing the solution", INDEX('AB Test Analysis'!$C$28:$C$29,1,1))) -> 9300
A6: 5 | B6: free response | D6: =IF(ISBLANK(INDEX('AB Test Analysis'!$A$39:$C$45,1,1)), "no solution", IF(ISERROR(INDEX('AB Test Analysis'!$A$39:$C$45,1,1)), "error in parsing the solution", INDEX('AB Test Analysis'!$A$39:$C$45,1,1))) -> One cofounding factor that could impact the experiment could be delivery time; which impacts when people are available to check their email and see the message. Additionally, is the device they are opening the email on, Whether that be phone or desktop the subject line could be truncated on mobile phones. To mitigate these issues you can make sure the emails are going out at the same time and design the subject line so that the offer is at the front.
A7: 7 | B7: 91 | D7: =IF(ISBLANK(INDEX('AB Test Analysis'!$C$53:$C$54,1,1)), "no solution", IF(ISERROR(INDEX('AB Test Analysis'!$C$53:$C$54,1,1)), "error in parsing the solution", INDEX('AB Test Analysis'!$C$53:$C$54,1,1))) -> 91
A8: 8 | B8: 58 | D8: =IF(ISBLANK(INDEX('AB Test Analysis'!$C$55:$C$56,1,1)), "no solution", IF(ISERROR(INDEX('AB Test Analysis'!$C$55:$C$56,1,1)), "error in parsing the solution", INDEX('AB Test Analysis'!$C$55:$C$56,1,1))) -> 58
A9: 9 | B9: free response | D9: =IF(ISBLANK(INDEX('AB Test Analysis'!$A$61:$C$65,1,1)), "no solution", IF(ISERROR(INDEX('AB Test Analysis'!$A$61:$C$65,1,1)), "error in parsing the solution", INDEX('AB Test Analysis'!$A$61:$C$65,1,1))) -> Test "B" converted 10% better than Test "A". I am 98% certain that the changes in Test "B" will improve your conversion rate. Your A/B test is statistically significant
A10: 10 | B10: free response | D10: =IF(ISBLANK(INDEX('AB Test Analysis'!$A$69:$C$71,1,1)), "no solution", IF(ISERROR(INDEX('AB Test Analysis'!$A$69:$C$71,1,1)), "error in parsing the solution", INDEX('AB Test Analysis'!$A$69:$C$71,1,1))) -> Based off the sample it is possible for us to encounter a sampling error. There potentially could be no real difference in the subject line performing better which would be a false positive.
A11: 11 | B11: free response | D11: =IF(ISBLANK(INDEX('AB Test Analysis'!$A$77:$C$81,1,1)), "no solution", IF(ISERROR(INDEX('AB Test Analysis'!$A$77:$C$81,1,1)), "error in parsing the solution", INDEX('AB Test Analysis'!$A$77:$C$81,1,1))) -> H&M should continue to send promotional emails with the new subject line because we are safely within the significance range needed for rejecting the null hypothesis. Although, its not the desired coversion rate, it still makes a big enough impact with litttle to no cost.
A12: 12 | B12: free response | D12: =IF(ISBLANK(INDEX('AB Test Analysis'!$A$89:$C$95,1,1)), "no solution", IF(ISERROR(INDEX('AB Test Analysis'!$A$89:$C$95,1,1)), "error in parsing the solution", INDEX('AB Test Analysis'!$A$89:$C$95,1,1))) -> I would balance these factors by focusing on what will drive the business sales rather than the open rate of an email. I would narrow my A/B testing to how many receipents actually make a purchase when they open the new subject line email. Addtional data to determine open rates translating to meaninful sales would be total revenue generated from each group
